{"links": {"self": {"href": "data/repositories/osrf/srcsim/issues/134/comments/36406140.json"}, "html": {"href": "#!/osrf/srcsim/issues/134#comment-36406140"}}, "issue": {"links": {"self": {"href": "data/repositories/osrf/srcsim/issues/134.json"}}, "type": "issue", "id": 134, "repository": {"links": {"self": {"href": "data/repositories/osrf/srcsim.json"}, "html": {"href": "#!/osrf/srcsim"}, "avatar": {"href": "data/bytebucket.org/ravatar/{c41021d9-0217-4628-999d-7f8d82f98dcb}ts=c_plus_plus"}}, "type": "repository", "name": "srcsim", "full_name": "osrf/srcsim", "uuid": "{c41021d9-0217-4628-999d-7f8d82f98dcb}"}, "title": "java.io.IOException: Too many open files"}, "content": {"raw": "Actually, to be more precise.  I'm seeing connection refused messages; I have not (yet) found the Java IO error.  So I may be conflating two issues; it just seems suspiciously similar.\n\nMy connection refused messages look like this:\n\n[rosmaster.master][INFO] 2017-04-29 13:46:59,581: publisherUpdate[/ihmc_ros/valkyrie/control/pelvis_orientation_trajectory] -> http://127.0.0.1:43115/\n[rosmaster.threadpool][ERROR] 2017-04-29 13:46:59,582: Traceback (most recent call last):\n  File \"/opt/ros/indigo/lib/python2.7/dist-packages/rosmaster/threadpool.py\", line 218, in run\n    result = cmd(*args)\n  File \"/opt/ros/indigo/lib/python2.7/dist-packages/rosmaster/master_api.py\", line 208, in publisher_update_task\n    xmlrpcapi(api).publisherUpdate('/master', topic, pub_uris)\n  File \"/usr/lib/python2.7/xmlrpclib.py\", line 1233, in __call__\n    return self.__send(self.__name, args)\n  File \"/usr/lib/python2.7/xmlrpclib.py\", line 1587, in __request\n    verbose=self.__verbose\n  File \"/usr/lib/python2.7/xmlrpclib.py\", line 1273, in request\n    return self.single_request(host, handler, request_body, verbose)\n  File \"/usr/lib/python2.7/xmlrpclib.py\", line 1301, in single_request\n    self.send_content(h, request_body)\n  File \"/usr/lib/python2.7/xmlrpclib.py\", line 1448, in send_content\n    connection.endheaders(request_body)\n  File \"/usr/lib/python2.7/httplib.py\", line 1013, in endheaders\n    self._send_output(message_body)\n  File \"/usr/lib/python2.7/httplib.py\", line 864, in _send_output\n    self.send(msg)\n  File \"/usr/lib/python2.7/httplib.py\", line 826, in send\n    self.connect()\n  File \"/usr/lib/python2.7/httplib.py\", line 807, in connect\n    self.timeout, self.source_address)\n  File \"/usr/lib/python2.7/socket.py\", line 571, in create_connection\n    raise err\nerror: [Errno 111] Connection refused", "markup": "markdown", "html": "<p>Actually, to be more precise.  I'm seeing connection refused messages; I have not (yet) found the Java IO error.  So I may be conflating two issues; it just seems suspiciously similar.</p>\n<p>My connection refused messages look like this:</p>\n<p>[rosmaster.master][INFO] 2017-04-29 13:46:59,581: publisherUpdate[/ihmc_ros/valkyrie/control/pelvis_orientation_trajectory] -&gt; <a href=\"http://127.0.0.1:43115/\" rel=\"nofollow\" class=\"ap-connect-link\">http://127.0.0.1:43115/</a>\n[rosmaster.threadpool][ERROR] 2017-04-29 13:46:59,582: Traceback (most recent call last):\n  File \"/opt/ros/indigo/lib/python2.7/dist-packages/rosmaster/threadpool.py\", line 218, in run\n    result = cmd(*args)\n  File \"/opt/ros/indigo/lib/python2.7/dist-packages/rosmaster/master_api.py\", line 208, in publisher_update_task\n    xmlrpcapi(api).publisherUpdate('/master', topic, pub_uris)\n  File \"/usr/lib/python2.7/xmlrpclib.py\", line 1233, in <strong>call</strong>\n    return self.<strong>send(self.</strong>name, args)\n  File \"/usr/lib/python2.7/xmlrpclib.py\", line 1587, in <strong>request\n    verbose=self.</strong>verbose\n  File \"/usr/lib/python2.7/xmlrpclib.py\", line 1273, in request\n    return self.single_request(host, handler, request_body, verbose)\n  File \"/usr/lib/python2.7/xmlrpclib.py\", line 1301, in single_request\n    self.send_content(h, request_body)\n  File \"/usr/lib/python2.7/xmlrpclib.py\", line 1448, in send_content\n    connection.endheaders(request_body)\n  File \"/usr/lib/python2.7/httplib.py\", line 1013, in endheaders\n    self._send_output(message_body)\n  File \"/usr/lib/python2.7/httplib.py\", line 864, in _send_output\n    self.send(msg)\n  File \"/usr/lib/python2.7/httplib.py\", line 826, in send\n    self.connect()\n  File \"/usr/lib/python2.7/httplib.py\", line 807, in connect\n    self.timeout, self.source_address)\n  File \"/usr/lib/python2.7/socket.py\", line 571, in create_connection\n    raise err\nerror: [Errno 111] Connection refused</p>", "type": "rendered"}, "created_on": "2017-04-29T18:55:20.870252+00:00", "user": {"display_name": "Jeremy White", "uuid": "{abab48b0-35b1-4102-8373-e88a492c5294}", "links": {"self": {"href": "https://api.bitbucket.org/2.0/users/%7Babab48b0-35b1-4102-8373-e88a492c5294%7D"}, "html": {"href": "https://bitbucket.org/%7Babab48b0-35b1-4102-8373-e88a492c5294%7D/"}, "avatar": {"href": "data/secure.gravatar.com/avatar/2764d3b5adf560de71f57e48a30550bad=httpsavatar-management--avatars.us-west-2.prod.public.atl-paas.netinitialsJW-3.png"}}, "nickname": "knitfoo", "type": "user", "account_id": "557058:5de786d6-615c-44ef-8e12-f079efa38357"}, "updated_on": null, "type": "issue_comment", "id": 36406140}